Exception ignored in: <function _ProactorBasePipeTransport.__del__ at 0x000002A0ACDFE280>
Traceback (most recent call last):
  File "C:\Users\gpu009\AppData\Local\Programs\Python\Python39\lib\asyncio\proactor_events.py", line 116, in 
__del__
    self.close()
  File "C:\Users\gpu009\AppData\Local\Programs\Python\Python39\lib\asyncio\proactor_events.py", line 108, in 
close
    self._loop.call_soon(self._call_connection_lost, None)
  File "C:\Users\gpu009\AppData\Local\Programs\Python\Python39\lib\asyncio\base_events.py", line 751, in call_soon
    self._check_closed()
  File "C:\Users\gpu009\AppData\Local\Programs\Python\Python39\lib\asyncio\base_events.py", line 515, in _check_closed
    raise RuntimeError('Event loop is closed')
RuntimeError: Event loop is closed
Exception ignored in: <function _ProactorBasePipeTransport.__del__ at 0x000002A0ACDFE280>
Traceback (most recent call last):
  File "C:\Users\gpu009\AppData\Local\Programs\Python\Python39\lib\asyncio\proactor_events.py", line 116, in 
__del__
    self.close()
  File "C:\Users\gpu009\AppData\Local\Programs\Python\Python39\lib\asyncio\proactor_events.py", line 108, in 
close
    self._loop.call_soon(self._call_connection_lost, None)
  File "C:\Users\gpu009\AppData\Local\Programs\Python\Python39\lib\asyncio\base_events.py", line 751, in call_soon
    self._check_closed()
  File "C:\Users\gpu009\AppData\Local\Programs\Python\Python39\lib\asyncio\base_events.py", line 515, in _check_closed
    raise RuntimeError('Event loop is closed')
RuntimeError: Event loop is closed
Exception ignored in: <function _ProactorBasePipeTransport.__del__ at 0x000002A0ACDFE280>
Traceback (most recent call last):
  File "C:\Users\gpu009\AppData\Local\Programs\Python\Python39\lib\asyncio\proactor_events.py", line 116, in 
__del__
    self.close()
  File "C:\Users\gpu009\AppData\Local\Programs\Python\Python39\lib\asyncio\proactor_events.py", line 108, in 
close
    self._loop.call_soon(self._call_connection_lost, None)
  File "C:\Users\gpu009\AppData\Local\Programs\Python\Python39\lib\asyncio\base_events.py", line 751, in call_soon
    self._check_closed()
  File "C:\Users\gpu009\AppData\Local\Programs\Python\Python39\lib\asyncio\base_events.py", line 515, in _check_closed
    raise RuntimeError('Event loop is closed')
RuntimeError: Event loop is closed
Exception ignored in: <function _ProactorBasePipeTransport.__del__ at 0x000002A0ACDFE280>
Traceback (most recent call last):
  File "C:\Users\gpu009\AppData\Local\Programs\Python\Python39\lib\asyncio\proactor_events.py", line 116, in 
__del__
    self.close()
  File "C:\Users\gpu009\AppData\Local\Programs\Python\Python39\lib\asyncio\proactor_events.py", line 108, in 
close
    self._loop.call_soon(self._call_connection_lost, None)
  File "C:\Users\gpu009\AppData\Local\Programs\Python\Python39\lib\asyncio\base_events.py", line 751, in call_soon
    self._check_closed()
  File "C:\Users\gpu009\AppData\Local\Programs\Python\Python39\lib\asyncio\base_events.py", line 515, in _check_closed
    raise RuntimeError('Event loop is closed')
RuntimeError: Event loop is closed
Exception ignored in: <function _ProactorBasePipeTransport.__del__ at 0x000002A0ACDFE280>
Traceback (most recent call last):
  File "C:\Users\gpu009\AppData\Local\Programs\Python\Python39\lib\asyncio\proactor_events.py", line 116, in 
__del__
    self.close()
  File "C:\Users\gpu009\AppData\Local\Programs\Python\Python39\lib\asyncio\proactor_events.py", line 108, in 
close
    self._loop.call_soon(self._call_connection_lost, None)
  File "C:\Users\gpu009\AppData\Local\Programs\Python\Python39\lib\asyncio\base_events.py", line 751, in call_soon
    self._check_closed()
  File "C:\Users\gpu009\AppData\Local\Programs\Python\Python39\lib\asyncio\base_events.py", line 515, in _check_closed
    raise RuntimeError('Event loop is closed')
RuntimeError: Event loop is closed
Exception ignored in: <function _ProactorBasePipeTransport.__del__ at 0x000002A0ACDFE280>
Traceback (most recent call last):
  File "C:\Users\gpu009\AppData\Local\Programs\Python\Python39\lib\asyncio\proactor_events.py", line 116, in 
__del__
    self.close()
  File "C:\Users\gpu009\AppData\Local\Programs\Python\Python39\lib\asyncio\proactor_events.py", line 108, in 
close
    self._loop.call_soon(self._call_connection_lost, None)
  File "C:\Users\gpu009\AppData\Local\Programs\Python\Python39\lib\asyncio\base_events.py", line 751, in call_soon
    self._check_closed()
  File "C:\Users\gpu009\AppData\Local\Programs\Python\Python39\lib\asyncio\base_events.py", line 515, in _check_closed
    raise RuntimeError('Event loop is closed')
RuntimeError: Event loop is closed